Workbook
Name hospital_details: '[1]Hospitalisation Details'!$A$2:$H$2344

Sheet Healthcare
A1: Customer ID | B1: First Name | C1: BMI | D1: Weight status | E1: HBA1C | F1: Diabetes status | G1: Heart Issues | H1: Any Transplants | I1: Cancer history | J1: NumberOfMajorSurgeries | K1: smoker | L1: Date OF Birth | M1: Age | N1: children | O1: $Currency | P1: Hospital tier | Q1: City tier | R1: State ID
A2: ID1 | B2: =VLOOKUP($A2,[1]!Customer_Names[#Data],3,0) -> Kelly | C2: 47.41 | D2: {=_xlfn.IFS(Healthcare!$C2<18.5,"under weight",Healthcare!$C2<=24.9,"Normal Weight",Healthcare!$C2>=25,"overweight",Healthcare!$C2>=30,"obese")} -> overweight | E2: 7.47 | F2: {=_xlfn.IFS(Healthcare!$E2<5.7,"normal",Healthcare!$E2<=6.4,"prediabetes",Healthcare!$E2>=6.5,"diabetes")} -> diabetes | G2: No | H2: No | I2: No | J2: 0 | K2: yes | L2: =VLOOKUP(Healthcare!$A2,hospital_details,2,0) -> 12-Oct-1968 | M2: =VLOOKUP(A2,hospital_details,3,0) -> 58 | N2: =VLOOKUP($A2,hospital_details,4,0) -> 0 | O2: =VLOOKUP($A2,hospital_details,5,0) -> 63770.43 | P2: =VLOOKUP($A2,hospital_details,6,0) -> tier - 1 | Q2: =VLOOKUP($A2,hospital_details,7,0) -> tier - 3 | R2: =VLOOKUP($A2,hospital_details,8,0) -> R1013
A3: ID2 | B3: =VLOOKUP($A3,[1]!Customer_Names[#Data],3,0) -> Matthew D | C3: 30.36 | D3: {=_xlfn.IFS(Healthcare!$C3<18.5,"under weight",Healthcare!$C3<=24.9,"Normal Weight",Healthcare!$C3>=25,"overweight",Healthcare!$C3>=30,"obese")} -> overweight | E3: 5.77 | F3: {=_xlfn.IFS(Healthcare!$E3<5.7,"normal",Healthcare!$E3<=6.4,"prediabetes",Healthcare!$E3>=6.5,"diabetes")} -> prediabetes | G3: No | H3: No | I3: No | J3: 0 | K3: yes | L3: =VLOOKUP(Healthcare!$A3,hospital_details,2,0) -> 8-Jun-1977 | M3: =VLOOKUP(A3,hospital_details,3,0) -> 49 | N3: =VLOOKUP($A3,hospital_details,4,0) -> 0 | O3: =VLOOKUP($A3,hospital_details,5,0) -> 62592.87 | P3: =VLOOKUP($A3,hospital_details,6,0) -> tier - 2 | Q3: =VLOOKUP($A3,hospital_details,7,0) -> tier - 3 | R3: =VLOOKUP($A3,hospital_details,8,0) -> R1013
A4: ID3 | B4: =VLOOKUP($A4,[1]!Customer_Names[#Data],3,0) -> Phil | C4: 34.485 | D4: {=_xlfn.IFS(Healthcare!$C4<18.5,"under weight",Healthcare!$C4<=24.9,"Normal Weight",Healthcare!$C4>=25,"overweight",Healthcare!$C4>=30,"obese")} -> overweight | E4: 11.87 | F4: {=_xlfn.IFS(Healthcare!$E4<5.7,"normal",Healthcare!$E4<=6.4,"prediabetes",Healthcare!$E4>=6.5,"diabetes")} -> diabetes | G4: yes | H4: No | I4: No | J4: 2 | K4: yes | L4: =VLOOKUP(Healthcare!$A4,hospital_details,2,0) -> 11-sep-1970 | M4: =VLOOKUP(A4,hospital_details,3,0) -> 56 | N4: =VLOOKUP($A4,hospital_details,4,0) -> 3 | O4: =VLOOKUP($A4,hospital_details,5,0) -> 60021.4 | P4: =VLOOKUP($A4,hospital_details,6,0) -> tier - 1 | Q4: =VLOOKUP($A4,hospital_details,7,0) -> tier - 1 | R4: =VLOOKUP($A4,hospital_details,8,0) -> R1012
A5: ID4 | B5: =VLOOKUP($A5,[1]!Customer_Names[#Data],3,0) -> Kelsey | C5: 38.095 | D5: {=_xlfn.IFS(Healthcare!$C5<18.5,"under weight",Healthcare!$C5<=24.9,"Normal Weight",Healthcare!$C5>=25,"overweight",Healthcare!$C5>=30,"obese")} -> overweight | E5: 6.05 | F5: {=_xlfn.IFS(Healthcare!$E5<5.7,"normal",Healthcare!$E5<=6.4,"prediabetes",Healthcare!$E5>=6.5,"diabetes")} -> prediabetes | G5: No | H5: No | I5: No | J5: 0 | K5: yes | L5: =VLOOKUP(Healthcare!$A5,hospital_details,2,0) -> 6-Jun-1991 | M5: =VLOOKUP(A5,hospital_details,3,0) -> 35 | N5: =VLOOKUP($A5,hospital_details,4,0) -> 1 | O5: =VLOOKUP($A5,hospital_details,5,0) -> 58571.07 | P5: =VLOOKUP($A5,hospital_details,6,0) -> tier - 1 | Q5: =VLOOKUP($A5,hospital_details,7,0) -> tier - 3 | R5: =VLOOKUP($A5,hospital_details,8,0) -> R1024
A6: ID5 | B6: =VLOOKUP($A6,[1]!Customer_Names[#Data],3,0) -> Kristyn | C6: 35.53 | D6: {=_xlfn.IFS(Healthcare!$C6<18.5,"under weight",Healthcare!$C6<=24.9,"Normal Weight",Healthcare!$C6>=25,"overweight",Healthcare!$C6>=30,"obese")} -> overweight | E6: 5.45 | F6: {=_xlfn.IFS(Healthcare!$E6<5.7,"normal",Healthcare!$E6<=6.4,"prediabetes",Healthcare!$E6>=6.5,"diabetes")} -> normal | G6: No | H6: No | I6: No | J6: 0 | K6: yes | L6: =VLOOKUP(Healthcare!$A6,hospital_details,2,0) -> 19-Jun-1989 | M6: =VLOOKUP(A6,hospital_details,3,0) -> 37 | N6: =VLOOKUP($A6,hospital_details,4,0) -> 0 | O6: =VLOOKUP($A6,hospital_details,5,0) -> 55135.4 | P6: =VLOOKUP($A6,hospital_details,6,0) -> tier - 1 | Q6: =VLOOKUP($A6,hospital_details,7,0) -> tier - 2 | R6: =VLOOKUP($A6,hospital_details,8,0) -> R1012
A7: ID6 | B7: =VLOOKUP($A7,[1]!Customer_Names[#Data],3,0) -> Russell B | C7: 32.8 | D7: {=_xlfn.IFS(Healthcare!$C7<18.5,"under weight",Healthcare!$C7<=24.9,"Normal Weight",Healthcare!$C7>=25,"overweight",Healthcare!$C7>=30,"obese")} -> overweight | E7: 6.59 | F7: {=_xlfn.IFS(Healthcare!$E7<5.7,"normal",Healthcare!$E7<=6.4,"prediabetes",Healthcare!$E7>=6.5,"diabetes")} -> diabetes | G7: No | H7: No | I7: No | J7: 0 | K7: yes | L7: =VLOOKUP(Healthcare!$A7,hospital_details,2,0) -> 4-Aug-1962 | M7: =VLOOKUP(A7,hospital_details,3,0) -> 64 | N7: =VLOOKUP($A7,hospital_details,4,0) -> 0 | O7: =VLOOKUP($A7,hospital_details,5,0) -> 52590.83 | P7: =VLOOKUP($A7,hospital_details,6,0) -> tier - 1 | Q7: =VLOOKUP($A7,hospital_details,7,0) -> tier - 3 | R7: =VLOOKUP($A7,hospital_details,8,0) -> R1011
A8: ID7 | B8: =VLOOKUP($A8,[1]!Customer_Names[#Data],3,0) -> Scott | C8: 36.4 | D8: {=_xlfn.IFS(Healthcare!$C8<18.5,"under weight",Healthcare!$C8<=24.9,"Normal Weight",Healthcare!$C8>=25,"overweight",Healthcare!$C8>=30,"obese")} -> overweight | E8: 6.07 | F8: {=_xlfn.IFS(Healthcare!$E8<5.7,"normal",Healthcare!$E8<=6.4,"prediabetes",Healthcare!$E8>=6.5,"diabetes")} -> prediabetes | G8: No | H8: No | I8: No | J8: 0 | K8: yes | L8: =VLOOKUP(Healthcare!$A8,hospital_details,2,0) -> 27-Oct-1994 | M8: =VLOOKUP(A8,hospital_details,3,0) -> 31 | N8: =VLOOKUP($A8,hospital_details,4,0) -> 1 | O8: =VLOOKUP($A8,hospital_details,5,0) -> 51194.56 | P8: =VLOOKUP($A8,hospital_details,6,0) -> tier - 1 | Q8: =VLOOKUP($A8,hospital_details,7,0) -> tier - 3 | R8: =VLOOKUP($A8,hospital_details,8,0) -> R1011
A9: ID8 | B9: =VLOOKUP($A9,[1]!Customer_Names[#Data],3,0) -> Stephen | C9: 36.96 | D9: {=_xlfn.IFS(Healthcare!$C9<18.5,"under weight",Healthcare!$C9<=24.9,"Normal Weight",Healthcare!$C9>=25,"overweight",Healthcare!$C9>=30,"obese")} -> overweight | E9: 7.93 | F9: {=_xlfn.IFS(Healthcare!$E9<5.7,"normal",Healthcare!$E9<=6.4,"prediabetes",Healthcare!$E9>=6.5,"diabetes")} -> diabetes | G9: No | H9: No | I9: No | J9: 3 | K9: yes | L9: =VLOOKUP(Healthcare!$A9,hospital_details,2,0) -> 27-Jun-1958 | M9: =VLOOKUP(A9,hospital_details,3,0) -> 68 | N9: =VLOOKUP($A9,hospital_details,4,0) -> 2 | O9: =VLOOKUP($A9,hospital_details,5,0) -> 49577.66 | P9: =VLOOKUP($A9,hospital_details,6,0) -> tier - 2 | Q9: =VLOOKUP($A9,hospital_details,7,0) -> tier - 2 | R9: =VLOOKUP($A9,hospital_details,8,0) -> R1013
A10: ID9 | B10: =VLOOKUP($A10,[1]!Customer_Names[#Data],3,0) -> Patrick R | C10: 41.14 | D10: {=_xlfn.IFS(Healthcare!$C10<18.5,"under weight",Healthcare!$C10<=24.9,"Normal Weight",Healthcare!$C10>=25,"overweight",Healthcare!$C10>=30,"obese")} -> overweight | E10: 9.58 | F10: {=_xlfn.IFS(Healthcare!$E10<5.7,"normal",Healthcare!$E10<=6.4,"prediabetes",Healthcare!$E10>=6.5,"diabetes")} -> diabetes | G10: yes | H10: No | I10: Yes | J10: 1 | K10: yes | L10: =VLOOKUP(Healthcare!$A10,hospital_details,2,0) -> 4-Sep-1963 | M10: =VLOOKUP(A10,hospital_details,3,0) -> 63 | N10: =VLOOKUP($A10,hospital_details,4,0) -> 1 | O10: =VLOOKUP($A10,hospital_details,5,0) -> 48970.25 | P10: =VLOOKUP($A10,hospital_details,6,0) -> tier - 1 | Q10: =VLOOKUP($A10,hospital_details,7,0) -> tier - 2 | R10: =VLOOKUP($A10,hospital_details,8,0) -> R1013
A11: ID10 | B11: =VLOOKUP($A11,[1]!Customer_Names[#Data],3,0) -> Brooke N | C11: 38.06 | D11: {=_xlfn.IFS(Healthcare!$C11<18.5,"under weight",Healthcare!$C11<=24.9,"Normal Weight",Healthcare!$C11>=25,"overweight",Healthcare!$C11>=30,"obese")} -> overweight | E11: 10.79 | F11: {=_xlfn.IFS(Healthcare!$E11<5.7,"normal",Healthcare!$E11<=6.4,"prediabetes",Healthcare!$E11>=6.5,"diabetes")} -> diabetes | G11: No | H11: No | I11: No | J11: 0 | K11: yes | L11: =VLOOKUP(Healthcare!$A11,hospital_details,2,0) -> 29-Dec-1978 | M11: =VLOOKUP(A11,hospital_details,3,0) -> 47 | N11: =VLOOKUP($A11,hospital_details,4,0) -> 0 | O11: =VLOOKUP($A11,hospital_details,5,0) -> 48885.14 | P11: =VLOOKUP($A11,hospital_details,6,0) -> tier - 1 | Q11: =VLOOKUP($A11,hospital_details,7,0) -> tier - 2 | R11: =VLOOKUP($A11,hospital_details,8,0) -> R1013
A12: ID11 | B12: =VLOOKUP($A12,[1]!Customer_Names[#Data],3,0) -> Paola Andrea | C12: 37.7 | D12: {=_xlfn.IFS(Healthcare!$C12<18.5,"under weight",Healthcare!$C12<=24.9,"Normal Weight",Healthcare!$C12>=25,"overweight",Healthcare!$C12>=30,"obese")} -> overweight | E12: 5.96 | F12: {=_xlfn.IFS(Healthcare!$E12<5.7,"normal",Healthcare!$E12<=6.4,"prediabetes",Healthcare!$E12>=6.5,"diabetes")} -> prediabetes | G12: yes | H12: No | I12: No | J12: 2 | K12: yes | L12: =VLOOKUP(Healthcare!$A12,hospital_details,2,0) -> 22-Jul-1959 | M12: =VLOOKUP(A12,hospital_details,3,0) -> 67 | N12: =VLOOKUP($A12,hospital_details,4,0) -> 0 | O12: =VLOOKUP($A12,hospital_details,5,0) -> 48824.45 | P12: =VLOOKUP($A12,hospital_details,6,0) -> tier - 2 | Q12: =VLOOKUP($A12,hospital_details,7,0) -> tier - 1 | R12: =VLOOKUP($A12,hospital_details,8,0) -> R1011
A13: ID12 | B13: =VLOOKUP($A13,[1]!Customer_Names[#Data],3,0) -> David | C13: 42.13 | D13: {=_xlfn.IFS(Healthcare!$C13<18.5,"under weight",Healthcare!$C13<=24.9,"Normal Weight",Healthcare!$C13>=25,"overweight",Healthcare!$C13>=30,"obese")} -> overweight | E13: 11.9 | F13: {=_xlfn.IFS(Healthcare!$E13<5.7,"normal",Healthcare!$E13<=6.4,"prediabetes",Healthcare!$E13>=6.5,"diabetes")} -> diabetes | G13: No | H13: No | I13: No | J13: 0 | K13: yes | L13: =VLOOKUP(Healthcare!$A13,hospital_details,2,0) -> 27-Oct-1965 | M13: =VLOOKUP(A13,hospital_details,3,0) -> 60 | N13: =VLOOKUP($A13,hospital_details,4,0) -> 1 | O13: =VLOOKUP($A13,hospital_details,5,0) -> 48675.52 | P13: =VLOOKUP($A13,hospital_details,6,0) -> tier - 1 | Q13: =VLOOKUP($A13,hospital_details,7,0) -> tier - 2 | R13: =VLOOKUP($A13,hospital_details,8,0) -> R1013
... A369: ID368 | B369: =VLOOKUP($A369,[1]!Customer_Names[#Data],3,0) -> Berenice | C369: 30.23 | D369: {=_xlfn.IFS(Healthcare!$C369<18.5,"under weight",Healthcare!$C369<=24.9,"Normal Weight",Healthcare!$C369>=25,"overweight",Healthcare!$C369>=30,"obese")} -> overweight | E369: 4.23 | F369: {=_xlfn.IFS(Healthcare!$E369<5.7,"normal",Healthcare!$E369<=6.4,"prediabetes",Healthcare!$E369>=6.5,"diabetes")} -> normal | G369: yes | H369: No | I369: Yes | J369: 1 | K369: yes | L369: =VLOOKUP(Healthcare!$A369,hospital_details,2,0) -> 7-Oct-1997 | M369: =VLOOKUP(A369,hospital_details,3,0) -> 29 | N369: =VLOOKUP($A369,hospital_details,4,0) -> 0 | O369: =VLOOKUP($A369,hospital_details,5,0) -> 27625.17 | P369: =VLOOKUP($A369,hospital_details,6,0) -> tier - 1 | Q369: =VLOOKUP($A369,hospital_details,7,0) -> tier - 1 | R369: =VLOOKUP($A369,hospital_details,8,0) -> R1011
A370: ID369 | B370: =VLOOKUP($A370,[1]!Customer_Names[#Data],3,0) -> Kenneth A | C370: 30.6 | D370: {=_xlfn.IFS(Healthcare!$C370<18.5,"under weight",Healthcare!$C370<=24.9,"Normal Weight",Healthcare!$C370>=25,"overweight",Healthcare!$C370>=30,"obese")} -> overweight | E370: 6.48 | F370: {=_xlfn.IFS(Healthcare!$E2<5.7,"normal",Healthcare!$E2<=6.4,"prediabetes",Healthcare!$E2>=6.5,"diabetes")} -> diabetes | G370: yes | H370: No | I370: Yes | J370: 1 | K370: yes | L370: =VLOOKUP(Healthcare!$A370,hospital_details,2,0) -> 9-Sep-1997 | M370: =VLOOKUP(A370,hospital_details,3,0) -> 29 | N370: =VLOOKUP($A370,hospital_details,4,0) -> 0 | O370: =VLOOKUP($A370,hospital_details,5,0) -> 27619.36 | P370: =VLOOKUP($A370,hospital_details,6,0) -> tier - 2 | Q370: =VLOOKUP($A370,hospital_details,7,0) -> tier - 3 | R370: =VLOOKUP($A370,hospital_details,8,0) -> R1011
A371: ID370 | B371: =VLOOKUP($A371,[1]!Customer_Names[#Data],3,0) -> Miguel | C371: 26.8 | D371: {=_xlfn.IFS(Healthcare!$C371<18.5,"under weight",Healthcare!$C371<=24.9,"Normal Weight",Healthcare!$C371>=25,"overweight",Healthcare!$C371>=30,"obese")} -> overweight | E371: 5.53 | F371: {=_xlfn.IFS(Healthcare!$E371<5.7,"normal",Healthcare!$E371<=6.4,"prediabetes",Healthcare!$E371>=6.5,"diabetes")} -> normal | G371: No | H371: No | I371: No | J371: 1 | K371: yes | L371: =VLOOKUP(Healthcare!$A371,hospital_details,2,0) -> 11-Jun-1992 | M371: =VLOOKUP(A371,hospital_details,3,0) -> 34 | N371: =VLOOKUP($A371,hospital_details,4,0) -> 0 | O371: =VLOOKUP($A371,hospital_details,5,0) -> 27614.71 | P371: =VLOOKUP($A371,hospital_details,6,0) -> tier - 2 | Q371: =VLOOKUP($A371,hospital_details,7,0) -> tier - 3 | R371: =VLOOKUP($A371,hospital_details,8,0) -> R1011
A372: ID371 | B372: =VLOOKUP($A372,[1]!Customer_Names[#Data],3,0) -> Hadley T | C372: 16.86 | D372: {=_xlfn.IFS(Healthcare!$C372<18.5,"under weight",Healthcare!$C372<=24.9,"Normal Weight",Healthcare!$C372>=25,"overweight",Healthcare!$C372>=30,"obese")} -> under weight | E372: 4.07 | F372: {=_xlfn.IFS(Healthcare!$E372<5.7,"normal",Healthcare!$E372<=6.4,"prediabetes",Healthcare!$E372>=6.5,"diabetes")} -> normal | G372: yes | H372: No | I372: No | J372: 0 | K372: yes | L372: =VLOOKUP(Healthcare!$A372,hospital_details,2,0) -> 6-Nov-1985 | M372: =VLOOKUP(A372,hospital_details,3,0) -> 40 | N372: =VLOOKUP($A372,hospital_details,4,0) -> 3 | O372: =VLOOKUP($A372,hospital_details,5,0) -> 27598.93 | P372: =VLOOKUP($A372,hospital_details,6,0) -> tier - 2 | Q372: =VLOOKUP($A372,hospital_details,7,0) -> tier - 1 | R372: =VLOOKUP($A372,hospital_details,8,0) -> R1011
A373: ID372 | B373: =VLOOKUP($A373,[1]!Customer_Names[#Data],3,0) -> Taylor | C373: 16.3 | D373: {=_xlfn.IFS(Healthcare!$C373<18.5,"under weight",Healthcare!$C373<=24.9,"Normal Weight",Healthcare!$C373>=25,"overweight",Healthcare!$C373>=30,"obese")} -> under weight | E373: 5.51 | F373: {=_xlfn.IFS(Healthcare!$E373<5.7,"normal",Healthcare!$E373<=6.4,"prediabetes",Healthcare!$E373>=6.5,"diabetes")} -> normal | G373: No | H373: No | I373: No | J373: 1 | K373: yes | L373: =VLOOKUP(Healthcare!$A373,hospital_details,2,0) -> 22-Jul-1984 | M373: =VLOOKUP(A373,hospital_details,3,0) -> 42 | N373: =VLOOKUP($A373,hospital_details,4,0) -> 3 | O373: =VLOOKUP($A373,hospital_details,5,0) -> 27534.53 | P373: =VLOOKUP($A373,hospital_details,6,0) -> tier - 2 | Q373: =VLOOKUP($A373,hospital_details,7,0) -> tier - 2 | R373: =VLOOKUP($A373,hospital_details,8,0) -> R1011
A374: ID373 | B374: =VLOOKUP($A374,[1]!Customer_Names[#Data],3,0) -> Tenielle M | C374: 29.81 | D374: {=_xlfn.IFS(Healthcare!$C374<18.5,"under weight",Healthcare!$C374<=24.9,"Normal Weight",Healthcare!$C374>=25,"overweight",Healthcare!$C374>=30,"obese")} -> overweight | E374: 11.66 | F374: {=_xlfn.IFS(Healthcare!$E374<5.7,"normal",Healthcare!$E374<=6.4,"prediabetes",Healthcare!$E374>=6.5,"diabetes")} -> diabetes | G374: No | H374: No | I374: No | J374: 0 | K374: yes | L374: =VLOOKUP(Healthcare!$A374,hospital_details,2,0) -> 19-Oct-1965 | M374: =VLOOKUP(A374,hospital_details,3,0) -> 60 | N374: =VLOOKUP($A374,hospital_details,4,0) -> 0 | O374: =VLOOKUP($A374,hospital_details,5,0) -> 27533.91 | P374: =VLOOKUP($A374,hospital_details,6,0) -> tier - 2 | Q374: =VLOOKUP($A374,hospital_details,7,0) -> tier - 3 | R374: =VLOOKUP($A374,hospital_details,8,0) -> R1013
A375: ID374 | B375: =VLOOKUP($A375,[1]!Customer_Names[#Data],3,0) -> Andrea | C375: 16.33 | D375: {=_xlfn.IFS(Healthcare!$C375<18.5,"under weight",Healthcare!$C375<=24.9,"Normal Weight",Healthcare!$C375>=25,"overweight",Healthcare!$C375>=30,"obese")} -> under weight | E375: 7.26 | F375: {=_xlfn.IFS(Healthcare!$E375<5.7,"normal",Healthcare!$E375<=6.4,"prediabetes",Healthcare!$E375>=6.5,"diabetes")} -> diabetes | G375: yes | H375: No | I375: No | J375: 0 | K375: yes | L375: =VLOOKUP(Healthcare!$A375,hospital_details,2,0) -> 3-Oct-1981 | M375: =VLOOKUP(A375,hospital_details,3,0) -> 45 | N375: =VLOOKUP($A375,hospital_details,4,0) -> 1 | O375: =VLOOKUP($A375,hospital_details,5,0) -> 27495.59 | P375: =VLOOKUP($A375,hospital_details,6,0) -> tier - 2 | Q375: =VLOOKUP($A375,hospital_details,7,0) -> tier - 1 | R375: =VLOOKUP($A375,hospital_details,8,0) -> R1011
A376: ID375 | B376: =VLOOKUP($A376,[1]!Customer_Names[#Data],3,0) -> Nora P | C376: 16.37 | D376: {=_xlfn.IFS(Healthcare!$C376<18.5,"under weight",Healthcare!$C376<=24.9,"Normal Weight",Healthcare!$C376>=25,"overweight",Healthcare!$C376>=30,"obese")} -> under weight | E376: 4.79 | F376: {=_xlfn.IFS(Healthcare!$E376<5.7,"normal",Healthcare!$E376<=6.4,"prediabetes",Healthcare!$E376>=6.5,"diabetes")} -> normal | G376: yes | H376: No | I376: No | J376: 0 | K376: yes | L376: =VLOOKUP(Healthcare!$A376,hospital_details,2,0) -> 5-Dec-1985 | M376: =VLOOKUP(A376,hospital_details,3,0) -> 40 | N376: =VLOOKUP($A376,hospital_details,4,0) -> 3 | O376: =VLOOKUP($A376,hospital_details,5,0) -> 27432.73 | P376: =VLOOKUP($A376,hospital_details,6,0) -> tier - 2 | Q376: =VLOOKUP($A376,hospital_details,7,0) -> tier - 1 | R376: =VLOOKUP($A376,hospital_details,8,0) -> R1011
A377: ID376 | B377: =VLOOKUP($A377,[1]!Customer_Names[#Data],3,0) -> Zachary | C377: 22.42 | D377: {=_xlfn.IFS(Healthcare!$C377<18.5,"under weight",Healthcare!$C377<=24.9,"Normal Weight",Healthcare!$C377>=25,"overweight",Healthcare!$C377>=30,"obese")} -> Normal Weight | E377: 4.68 | F377: {=_xlfn.IFS(Healthcare!$E377<5.7,"normal",Healthcare!$E377<=6.4,"prediabetes",Healthcare!$E377>=6.5,"diabetes")} -> normal | G377: yes | H377: No | I377: No | J377: 1 | K377: No | L377: =VLOOKUP(Healthcare!$A377,hospital_details,2,0) -> 15-Sep-1988 | M377: =VLOOKUP(A377,hospital_details,3,0) -> 38 | N377: =VLOOKUP($A377,hospital_details,4,0) -> 2 | O377: =VLOOKUP($A377,hospital_details,5,0) -> 27375.9 | P377: =VLOOKUP($A377,hospital_details,6,0) -> tier - 2 | Q377: =VLOOKUP($A377,hospital_details,7,0) -> tier - 3 | R377: =VLOOKUP($A377,hospital_details,8,0) -> R1015
A378: ID377 | B378: =VLOOKUP($A378,[1]!Customer_Names[#Data],3,0) -> Michael | C378: 31.35 | D378: {=_xlfn.IFS(Healthcare!$C378<18.5,"under weight",Healthcare!$C378<=24.9,"Normal Weight",Healthcare!$C378>=25,"overweight",Healthcare!$C378>=30,"obese")} -> overweight | E378: 4.33 | F378: {=_xlfn.IFS(Healthcare!$E378<5.7,"normal",Healthcare!$E378<=6.4,"prediabetes",Healthcare!$E378>=6.5,"diabetes")} -> normal | G378: yes | H378: No | I378: Yes | J378: 1 | K378: No | L378: =VLOOKUP(Healthcare!$A378,hospital_details,2,0) -> 16-Oct-1969 | M378: =VLOOKUP(A378,hospital_details,3,0) -> 57 | N378: =VLOOKUP($A378,hospital_details,4,0) -> 0 | O378: =VLOOKUP($A378,hospital_details,5,0) -> 27346.04 | P378: =VLOOKUP($A378,hospital_details,6,0) -> tier - 2 | Q378: =VLOOKUP($A378,hospital_details,7,0) -> tier - 2 | R378: =VLOOKUP($A378,hospital_details,8,0) -> R1013
A379: ID378 | B379: =VLOOKUP($A379,[1]!Customer_Names[#Data],3,0) -> Alyssa K | C379: 31.9 | D379: {=_xlfn.IFS(Healthcare!$C379<18.5,"under weight",Healthcare!$C379<=24.9,"Normal Weight",Healthcare!$C379>=25,"overweight",Healthcare!$C379>=30,"obese")} -> overweight | E379: 11.89 | F379: {=_xlfn.IFS(Healthcare!$E379<5.7,"normal",Healthcare!$E379<=6.4,"prediabetes",Healthcare!$E379>=6.5,"diabetes")} -> diabetes | G379: No | H379: No | I379: No | J379: 0 | K379: No | L379: =VLOOKUP(Healthcare!$A379,hospital_details,2,0) -> 6-Jun-1968 | M379: =VLOOKUP(A379,hospital_details,3,0) -> 58 | N379: =VLOOKUP($A379,hospital_details,4,0) -> 3 | O379: =VLOOKUP($A379,hospital_details,5,0) -> 27322.73 | P379: =VLOOKUP($A379,hospital_details,6,0) -> tier - 2 | Q379: =VLOOKUP($A379,hospital_details,7,0) -> tier - 2 | R379: =VLOOKUP($A379,hospital_details,8,0) -> R1013
A380: ID379 | B380: =VLOOKUP($A380,[1]!Customer_Names[#Data],3,0) -> Heather | C380: 30.6 | D380: {=_xlfn.IFS(Healthcare!$C380<18.5,"under weight",Healthcare!$C380<=24.9,"Normal Weight",Healthcare!$C380>=25,"overweight",Healthcare!$C380>=30,"obese")} -> overweight | E380: 5.24 | F380: {=_xlfn.IFS(Healthcare!$E380<5.7,"normal",Healthcare!$E380<=6.4,"prediabetes",Healthcare!$E380>=6.5,"diabetes")} -> normal | G380: No | H380: No | I380: No | J380: 0 | K380: yes | L380: =VLOOKUP(Healthcare!$A380,hospital_details,2,0) -> 2-Dec-1999 | M380: =VLOOKUP(A380,hospital_details,3,0) -> 26 | N380: =VLOOKUP($A380,hospital_details,4,0) -> 0 | O380: =VLOOKUP($A380,hospital_details,5,0) -> 27236.96 | P380: =VLOOKUP($A380,hospital_details,6,0) -> tier - 2 | Q380: =VLOOKUP($A380,hospital_details,7,0) -> tier - 1 | R380: =VLOOKUP($A380,hospital_details,8,0) -> R1011
A381: ID380 | B381: =VLOOKUP($A381,[1]!Customer_Names[#Data],3,0) -> Dante | C381: 28.975 | D381: {=_xlfn.IFS(Healthcare!$C381<18.5,"under weight",Healthcare!$C381<=24.9,"Normal Weight",Healthcare!$C381>=25,"overweight",Healthcare!$C381>=30,"obese")} -> overweight | E381: 7.63 | F381: {=_xlfn.IFS(Healthcare!$E381<5.7,"normal",Healthcare!$E381<=6.4,"prediabetes",Healthcare!$E381>=6.5,"diabetes")} -> diabetes | G381: No | H381: No | I381: No | J381: 0 | K381: yes | L381: =VLOOKUP(Healthcare!$A381,hospital_details,2,0) -> 21-Dec-1965 | M381: =VLOOKUP(A381,hospital_details,3,0) -> 60 | N381: =VLOOKUP($A381,hospital_details,4,0) -> 0 | O381: =VLOOKUP($A381,hospital_details,5,0) -> 27218.44 | P381: =VLOOKUP($A381,hospital_details,6,0) -> tier - 2 | Q381: =VLOOKUP($A381,hospital_details,7,0) -> tier - 1 | R381: =VLOOKUP($A381,hospital_details,8,0) -> R1017
A382: ID381 | B382: =VLOOKUP($A382,[1]!Customer_Names[#Data],3,0) -> Sara E | C382: 24.86 | D382: {=_xlfn.IFS(Healthcare!$C382<18.5,"under weight",Healthcare!$C382<=24.9,"Normal Weight",Healthcare!$C382>=25,"overweight",Healthcare!$C382>=30,"obese")} -> Normal Weight | E382: 8.92 | F382: {=_xlfn.IFS(Healthcare!$E382<5.7,"normal",Healthcare!$E382<=6.4,"prediabetes",Healthcare!$E382>=6.5,"diabetes")} -> diabetes | G382: yes | H382: No | I382: No | J382: 2 | K382: No | L382: =VLOOKUP(Healthcare!$A382,hospital_details,2,0) -> 2-Oct-1970 | M382: =VLOOKUP(A382,hospital_details,3,0) -> 56 | N382: =VLOOKUP($A382,hospital_details,4,0) -> 0 | O382: =VLOOKUP($A382,hospital_details,5,0) -> 27117.99 | P382: =VLOOKUP($A382,hospital_details,6,0) -> tier - 2 | Q382: =VLOOKUP($A382,hospital_details,7,0) -> tier - 2 | R382: =VLOOKUP($A382,hospital_details,8,0) -> R1013
... A442: ID441 | B442: =VLOOKUP($A442,[1]!Customer_Names[#Data],3,0) -> Denise M | C442: 22.88 | D442: {=_xlfn.IFS(Healthcare!$C442<18.5,"under weight",Healthcare!$C442<=24.9,"Normal Weight",Healthcare!$C442>=25,"overweight",Healthcare!$C442>=30,"obese")} -> Normal Weight | E442: 5.71 | F442: {=_xlfn.IFS(Healthcare!$E442<5.7,"normal",Healthcare!$E442<=6.4,"prediabetes",Healthcare!$E442>=6.5,"diabetes")} -> prediabetes | G442: yes | H442: No | I442: Yes | J442: 1 | K442: yes | L442: =VLOOKUP(Healthcare!$A442,hospital_details,2,0) -> 14-Nov-1969 | M442: =VLOOKUP(A442,hospital_details,3,0) -> 56 | N442: =VLOOKUP($A442,hospital_details,4,0) -> 1 | O442: =VLOOKUP($A442,hospital_details,5,0) -> 23244.79 | P442: =VLOOKUP($A442,hospital_details,6,0) -> tier - 2 | Q442: =VLOOKUP($A442,hospital_details,7,0) -> tier - 3 | R442: =VLOOKUP($A442,hospital_details,8,0) -> R1013
A443: ID442 | B443: =VLOOKUP($A443,[1]!Customer_Names[#Data],3,0) -> Peter R | C443: 24.985 | D443: {=_xlfn.IFS(Healthcare!$C2<18.5,"under weight",Healthcare!$C2<=24.9,"Normal Weight",Healthcare!$C2>=25,"overweight",Healthcare!$C2>=30,"obese")} -> overweight | E443: 4.43 | F443: {=_xlfn.IFS(Healthcare!$E443<5.7,"normal",Healthcare!$E443<=6.4,"prediabetes",Healthcare!$E443>=6.5,"diabetes")} -> normal | G443: yes | H443: No | I443: Yes | J443: 1 | K443: No | L443: =VLOOKUP(Healthcare!$A443,hospital_details,2,0) -> 7-Aug-1997 | M443: =VLOOKUP(A443,hospital_details,3,0) -> 29 | N443: =VLOOKUP($A443,hospital_details,4,0) -> 2 | O443: =VLOOKUP($A443,hospital_details,5,0) -> 23241.47 | P443: =VLOOKUP($A443,hospital_details,6,0) -> tier - 2 | Q443: =VLOOKUP($A443,hospital_details,7,0) -> tier - 3 | R443: =VLOOKUP($A443,hospital_details,8,0) -> R1018
A444: ID443 | B444: =VLOOKUP($A444,[1]!Customer_Names[#Data],3,0) -> Johnson K | C444: 33.1 | D444: {=_xlfn.IFS(Healthcare!$C444<18.5,"under weight",Healthcare!$C444<=24.9,"Normal Weight",Healthcare!$C444>=25,"overweight",Healthcare!$C444>=30,"obese")} -> overweight | E444: 5.52 | F444: {=_xlfn.IFS(Healthcare!$E444<5.7,"normal",Healthcare!$E444<=6.4,"prediabetes",Healthcare!$E444>=6.5,"diabetes")} -> normal | G444: No | H444: No | I444: Yes | J444: 1 | K444: No | L444: =VLOOKUP(Healthcare!$A444,hospital_details,2,0) -> 14-Dec-2003 | M444: =VLOOKUP(A444,hospital_details,3,0) -> 22 | N444: =VLOOKUP($A444,hospital_details,4,0) -> 0 | O444: =VLOOKUP($A444,hospital_details,5,0) -> 23082.96 | P444: =VLOOKUP($A444,hospital_details,6,0) -> tier - 2 | Q444: =VLOOKUP($A444,hospital_details,7,0) -> tier - 2 | R444: =VLOOKUP($A444,hospital_details,8,0) -> R1011
A445: ID444 | B445: =VLOOKUP($A445,[1]!Customer_Names[#Data],3,0) -> Katherine | C445: 27.83 | D445: {=_xlfn.IFS(Healthcare!$C445<18.5,"under weight",Healthcare!$C445<=24.9,"Normal Weight",Healthcare!$C445>=25,"overweight",Healthcare!$C445>=30,"obese")} -> overweight | E445: 9.2 | F445: {=_xlfn.IFS(Healthcare!$E445<5.7,"normal",Healthcare!$E445<=6.4,"prediabetes",Healthcare!$E445>=6.5,"diabetes")} -> diabetes | G445: yes | H445: No | I445: No | J445: 1 | K445: yes | L445: =VLOOKUP(Healthcare!$A445,hospital_details,2,0) -> 9-Sep-1975 | M445: =VLOOKUP(A445,hospital_details,3,0) -> 51 | N445: =VLOOKUP($A445,hospital_details,4,0) -> 0 | O445: =VLOOKUP($A445,hospital_details,5,0) -> 23065.42 | P445: =VLOOKUP($A445,hospital_details,6,0) -> tier - 2 | Q445: =VLOOKUP($A445,hospital_details,7,0) -> tier - 2 | R445: =VLOOKUP($A445,hospital_details,8,0) -> R1013
A446: ID445 | B446: =VLOOKUP($A446,[1]!Customer_Names[#Data],3,0) -> Lynda | C446: 30.875 | D446: {=_xlfn.IFS(Healthcare!$C446<18.5,"under weight",Healthcare!$C446<=24.9,"Normal Weight",Healthcare!$C446>=25,"overweight",Healthcare!$C446>=30,"obese")} -> overweight | E446: 10.97 | F446: {=_xlfn.IFS(Healthcare!$E446<5.7,"normal",Healthcare!$E446<=6.4,"prediabetes",Healthcare!$E446>=6.5,"diabetes")} -> diabetes | G446: yes | H446: No | I446: No | J446: 2 | K446: No | L446: =VLOOKUP(Healthcare!$A446,hospital_details,2,0) -> 9-Nov-1970 | M446: =VLOOKUP(A446,hospital_details,3,0) -> 55 | N446: =VLOOKUP($A446,hospital_details,4,0) -> 0 | O446: =VLOOKUP($A446,hospital_details,5,0) -> 23045.57 | P446: =VLOOKUP($A446,hospital_details,6,0) -> tier - 2 | Q446: =VLOOKUP($A446,hospital_details,7,0) -> tier - 2 | R446: =VLOOKUP($A446,hospital_details,8,0) -> R1024
A447: ID446 | B447: =VLOOKUP($A447,[1]!Customer_Names[#Data],3,0) -> Anthony | C447: 27.265 | D447: {=_xlfn.IFS(Healthcare!$C447<18.5,"under weight",Healthcare!$C447<=24.9,"Normal Weight",Healthcare!$C447>=25,"overweight",Healthcare!$C447>=30,"obese")} -> overweight | E447: 4.25 | F447: {=_xlfn.IFS(Healthcare!$E447<5.7,"normal",Healthcare!$E447<=6.4,"prediabetes",Healthcare!$E447>=6.5,"diabetes")} -> normal | G447: No | H447: No | I447: Yes | J447: 1 | K447: No | L447: =VLOOKUP(Healthcare!$A447,hospital_details,2,0) -> 25-Jul-2003 | M447: =VLOOKUP(A447,hospital_details,3,0) -> 23 | N447: =VLOOKUP($A447,hospital_details,4,0) -> 2 | O447: =VLOOKUP($A447,hospital_details,5,0) -> 22493.66 | P447: =VLOOKUP($A447,hospital_details,6,0) -> tier - 2 | Q447: =VLOOKUP($A447,hospital_details,7,0) -> tier - 1 | R447: =VLOOKUP($A447,hospital_details,8,0) -> R1012
A448: ID447 | B448: =VLOOKUP($A448,[1]!Customer_Names[#Data],3,0) -> Linnea C | C448: 26.7 | D448: {=_xlfn.IFS(Healthcare!$C448<18.5,"under weight",Healthcare!$C448<=24.9,"Normal Weight",Healthcare!$C448>=25,"overweight",Healthcare!$C448>=30,"obese")} -> overweight | E448: 5.23 | F448: {=_xlfn.IFS(Healthcare!$E448<5.7,"normal",Healthcare!$E448<=6.4,"prediabetes",Healthcare!$E448>=6.5,"diabetes")} -> normal | G448: No | H448: No | I448: Yes | J448: 1 | K448: yes | L448: =VLOOKUP(Healthcare!$A448,hospital_details,2,0) -> 14-Nov-1979 | M448: =VLOOKUP(A448,hospital_details,3,0) -> 46 | N448: =VLOOKUP($A448,hospital_details,4,0) -> 2 | O448: =VLOOKUP($A448,hospital_details,5,0) -> 22478.6 | P448: =VLOOKUP($A448,hospital_details,6,0) -> tier - 3 | Q448: =VLOOKUP($A448,hospital_details,7,0) -> tier - 2 | R448: =VLOOKUP($A448,hospital_details,8,0) -> R1011
A449: ID448 | B449: =VLOOKUP($A449,[1]!Customer_Names[#Data],3,0) -> Massimiliano A | C449: 29.925 | D449: {=_xlfn.IFS(Healthcare!$C449<18.5,"under weight",Healthcare!$C449<=24.9,"Normal Weight",Healthcare!$C449>=25,"overweight",Healthcare!$C449>=30,"obese")} -> overweight | E449: 5.96 | F449: {=_xlfn.IFS(Healthcare!$E449<5.7,"normal",Healthcare!$E449<=6.4,"prediabetes",Healthcare!$E449>=6.5,"diabetes")} -> prediabetes | G449: yes | H449: No | I449: Yes | J449: 1 | K449: yes | L449: =VLOOKUP(Healthcare!$A449,hospital_details,2,0) -> 21-Dec-1983 | M449: =VLOOKUP(A449,hospital_details,3,0) -> 42 | N449: =VLOOKUP($A449,hospital_details,4,0) -> 1 | O449: =VLOOKUP($A449,hospital_details,5,0) -> 22462.04 | P449: =VLOOKUP($A449,hospital_details,6,0) -> tier - 3 | Q449: =VLOOKUP($A449,hospital_details,7,0) -> tier - 1 | R449: =VLOOKUP($A449,hospital_details,8,0) -> R1019
A450: ID449 | B450: =VLOOKUP($A450,[1]!Customer_Names[#Data],3,0) -> James M | C450: 19.95 | D450: {=_xlfn.IFS(Healthcare!$C450<18.5,"under weight",Healthcare!$C450<=24.9,"Normal Weight",Healthcare!$C450>=25,"overweight",Healthcare!$C450>=30,"obese")} -> Normal Weight | E450: 4.29 | F450: {=_xlfn.IFS(Healthcare!$E450<5.7,"normal",Healthcare!$E450<=6.4,"prediabetes",Healthcare!$E450>=6.5,"diabetes")} -> normal | G450: yes | H450: No | I450: No | J450: 2 | K450: yes | L450: =VLOOKUP(Healthcare!$A450,hospital_details,2,0) -> 18-Aug-1966 | M450: =VLOOKUP(A450,hospital_details,3,0) -> 60 | N450: =VLOOKUP($A450,hospital_details,4,0) -> 0 | O450: =VLOOKUP($A450,hospital_details,5,0) -> 22412.65 | P450: =VLOOKUP($A450,hospital_details,6,0) -> tier - 3 | Q450: =VLOOKUP($A450,hospital_details,7,0) -> tier - 3 | R450: =VLOOKUP($A450,hospital_details,8,0) -> R1014
A451: ID450 | B451: =VLOOKUP($A451,[1]!Customer_Names[#Data],3,0) -> Lauren | C451: 24.225 | D451: {=_xlfn.IFS(Healthcare!$C451<18.5,"under weight",Healthcare!$C451<=24.9,"Normal Weight",Healthcare!$C451>=25,"overweight",Healthcare!$C451>=30,"obese")} -> Normal Weight | E451: 4.09 | F451: {=_xlfn.IFS(Healthcare!$E451<5.7,"normal",Healthcare!$E451<=6.4,"prediabetes",Healthcare!$E451>=6.5,"diabetes")} -> normal | G451: No | H451: No | I451: No | J451: 0 | K451: No | L451: =VLOOKUP(Healthcare!$A451,hospital_details,2,0) -> 26-Aug-1999 | M451: =VLOOKUP(A451,hospital_details,3,0) -> 27 | N451: =VLOOKUP($A451,hospital_details,4,0) -> 2 | O451: =VLOOKUP($A451,hospital_details,5,0) -> 22395.74 | P451: =VLOOKUP($A451,hospital_details,6,0) -> tier - 3 | Q451: =VLOOKUP($A451,hospital_details,7,0) -> tier - 2 | R451: =VLOOKUP($A451,hospital_details,8,0) -> R1024
A452: ID451 | B452: =VLOOKUP($A452,[1]!Customer_Names[#Data],3,0) -> Michele V | C452: 28.12 | D452: {=_xlfn.IFS(Healthcare!$C452<18.5,"under weight",Healthcare!$C452<=24.9,"Normal Weight",Healthcare!$C452>=25,"overweight",Healthcare!$C452>=30,"obese")} -> overweight | E452: 4.88 | F452: {=_xlfn.IFS(Healthcare!$E452<5.7,"normal",Healthcare!$E452<=6.4,"prediabetes",Healthcare!$E452>=6.5,"diabetes")} -> normal | G452: No | H452: No | I452: No | J452: 0 | K452: yes | L452: =VLOOKUP(Healthcare!$A452,hospital_details,2,0) -> 27-Dec-1982 | M452: =VLOOKUP(A452,hospital_details,3,0) -> 43 | N452: =VLOOKUP($A452,hospital_details,4,0) -> 1 | O452: =VLOOKUP($A452,hospital_details,5,0) -> 22331.57 | P452: =VLOOKUP($A452,hospital_details,6,0) -> tier - 2 | Q452: =VLOOKUP($A452,hospital_details,7,0) -> tier - 3 | R452: =VLOOKUP($A452,hospital_details,8,0) -> R1024
A453: ID452 | B453: =VLOOKUP($A453,[1]!Customer_Names[#Data],3,0) -> Xiao | C453: 23.21 | D453: {=_xlfn.IFS(Healthcare!$C453<18.5,"under weight",Healthcare!$C453<=24.9,"Normal Weight",Healthcare!$C453>=25,"overweight",Healthcare!$C453>=30,"obese")} -> Normal Weight | E453: 6.76 | F453: {=_xlfn.IFS(Healthcare!$E453<5.7,"normal",Healthcare!$E453<=6.4,"prediabetes",Healthcare!$E453>=6.5,"diabetes")} -> diabetes | G453: No | H453: No | I453: No | J453: 0 | K453: yes | L453: =VLOOKUP(Healthcare!$A453,hospital_details,2,0) -> 16-Jun-1971 | M453: =VLOOKUP(A453,hospital_details,3,0) -> 55 | N453: =VLOOKUP($A453,hospital_details,4,0) -> 1 | O453: =VLOOKUP($A453,hospital_details,5,0) -> 22218.11 | P453: =VLOOKUP($A453,hospital_details,6,0) -> tier - 2 | Q453: =VLOOKUP($A453,hospital_details,7,0) -> tier - 3 | R453: =VLOOKUP($A453,hospital_details,8,0) -> R1013
A454: ID453 | B454: =VLOOKUP($A454,[1]!Customer_Names[#Data],3,0) -> Harper L | C454: 23.98 | D454: {=_xlfn.IFS(Healthcare!$C454<18.5,"under weight",Healthcare!$C454<=24.9,"Normal Weight",Healthcare!$C454>=25,"overweight",Healthcare!$C454>=30,"obese")} -> Normal Weight | E454: 10.67 | F454: {=_xlfn.IFS(Healthcare!$E454<5.7,"normal",Healthcare!$E454<=6.4,"prediabetes",Healthcare!$E454>=6.5,"diabetes")} -> diabetes | G454: No | H454: No | I454: No | J454: 0 | K454: No | L454: =VLOOKUP(Healthcare!$A454,hospital_details,2,0) -> 24-Aug-1965 | M454: =VLOOKUP(A454,hospital_details,3,0) -> 61 | N454: =VLOOKUP($A454,hospital_details,4,0) -> 1 | O454: =VLOOKUP($A454,hospital_details,5,0) -> 22192.44 | P454: =VLOOKUP($A454,hospital_details,6,0) -> tier - 3 | Q454: =VLOOKUP($A454,hospital_details,7,0) -> tier - 1 | R454: =VLOOKUP($A454,hospital_details,8,0) -> R1013
...

Sheet Dashboard
